Workbook

Sheet 1
Z2: SHIRORO OPERATIONS REGION HOURLY READINGS
A10: 46113 | D10: SHIRORO 330/132KV TS | BD10: SHIRORO II TS | BM10: JEBBA 330/132KV TS | DE10: JEBBA 132/33KV | DN10: KAINJI/FAKUM 330132KV | EE10: ZUNGERU 330/132KV TS | GA10: MARARABA 33KV TS | GZ10: MINNA 132KV TS | HY10: TEGINA 132KV | IH10: BIDA 132KV TS | IY10: DOGON GARI 132KV TS | JP10: KONTAGORA 132KV TS | KG10: YAURI 132KV TS | KX10: SOKOTO 132KV TS | LP10: BIRNIN KEBBI 330/132KV TS | MP10: BIRNIN KEBBI 132KV TS
E12: 2SHR TR1 | L12: 2SHR TR2 | S12: 2SHR-KTP 1 | W12: 2SHR-GWA1 | AA12: 2SHR-MND1 | AE12: 2SHR-MND2 | AI12: 2SHR-MRB1 | AM12: 2SHR-MRB2 | AQ12: 3SHR-MNA1 | AU12: 3SHR-MNA2 | AY12: 3SHR-TEG1 | BD12: 3SHRTR1 | BM12: 2JEB TR1 | BU12: 2JEB-JEG 1 | BY12: 2JEB-JEG 2 | CC12: 2JEB-KNJ1 | CG12: 2JEB-KNJ2 | CK12: 2JEB-SGB1 | CO12: 2JEB-SGB2 | CS12: 2JEB-GAM 1 | CW12: 2JEB-MRB 1 | DA12: 2JEB-MRB 2 | DE12: 3JEBTR2 | DN12: 2FAK TR1 | DV12: 2KNJ-JEB 1 | DZ12: 2KNJ -JEB 2 | EE12: 2ZGU TR 1 | EM12: 2ZGU TR 2 | ET12: CCT 1ZGU1 | EX12: CCT 1ZGU 2 | FB12: CCT 1ZGU 3 | FF12: CCT 1ZGU 4 | FJ12: 2ZGU-MRB1 | FN12: 2ZGU-MRB2 | FR12: 3ZGU-TEG1 | FV12: 3ZGU-TEG | GA12: 2MRB- SHR1 | GE12: 2MRB- SHR2 | GI12: 2MRB-ZGU1 | GM12: 2 MRB-ZGU2 | GQ12: 2MRB-JEB1 | GU12: 2 MRB-JEB2 | GZ12: 3MNA TR1 | HH12: 3MNA TR2 | HP12: 3MNA TR1 | HY12: 3TEG TR1 | IH12: 3BDA TR5 | IP12: 3BDA TR2 | IY12: 3DGR TR1 | JG12: 3DGR TR2 | JP12: 3KNT TR1 | JX12: 3KNT TR2 | KG12: 3YUR TR1 | KO12: 3YAU TR2 | KX12: 3SOK TR1 | LF12: 3SOK TR3 | LP12: 2KNJ-BRK1 | LS12: 2BRK TR1 | MA12: 2BRK TR2 | MH12: 2BRK TR3 | MP12: 3BRK TR4 | NA12: 3BRKTR5 | NI12: 3BRKTR6
A13: TIME (HRS | C13: FREQ. (HZ) | D13: 330KV | E13: 132KV | F13: AMP | G13: MW | H13: MX | I13: TAP | J13: WIND | K13: OIL | L13: 132KV | M13: AMP | N13: MW | O13: MX | P13: TAP | Q13: WIND | R13: OIL | S13: 330KV | T13: AMP | U13: MW | V13: MX | W13: 330KV | X13: AMP | Y13: MW | Z13: MX | AA13: 330KV | AB13: AMP | AC13: MW | AD13: MX | AE13: 330KV | AF13: AMP | AG13: MW | AH13: MX | AI13: 330KV | AJ13: AMP | AK13: MW | AL13: MX | AM13: 330KV | AN13: AMP | AO13: MW | AP13: MX | AQ13: 132KV | AR13: AMP | AS13: MW | AT13: MX | AU13: 132KV | AV13: AMP | AW13: MW | AX13: MX | AY13: 132KV | AZ13: AMP | BA13: MW | BB13: MX | BD13: 132KV | BE13: 33KV | BF13: AMP | BG13: MW | BH13: MX | BI13: TAP | BJ13: WIND | BK13: OIL | BM13: 330KV | BN13: 132KV | BO13: AMP | BP13: MW | BQ13: MX | BR13: TAP | BS13: WIND | BT13: OIL | BU13: 330KV | BV13: AMP | BW13: MW | BX13: MX | BY13: 330KV | BZ13: AMP | CA13: MW | CB13: MX | CC13: 330KV | CD13: AMP | CE13: MW | CF13: MX | CG13: 330KV | CH13: AMP | CI13: MW | CJ13: MX | CK13: 330KV | CL13: AMP | CM13: MW | CN13: MX | CO13: 330KV | CP13: AMP | CQ13: MW | CR13: MX | CS13: 330KV | CT13: AMP | CU13: MW | CV13: MX | CW13: 330KV | CX13: AMP | CY13: MW | CZ13: MX | DA13: 330KV | DB13: AMP | DC13: MW | DD13: MX | DE13: 132KV | DF13: 33KV | DG13: AMP | DH13: MW | DI13: MX | DJ13: TAP | DK13: WIND | DL13: OIL | DN13: 330KV | DO13: 132KV | DP13: AMP | DQ13: MW | DR13: MX | DS13: TAP | DT13: WIND | DU13: OIL | DV13: 330KV | DW13: AMP | DX13: MW | DY13: MX | DZ13: 330KV | EA13: AMP | EB13: MW | EC13: MX | EE13: 330KV | EF13: 132KV | EG13: AMP | EH13: MW | EI13: MX | EJ13: TAP | EK13: WIND | EL13: OIL | EN13: AMP | EO13: MW | EP13: MX | EQ13: TAP | ER13: WIND | ES13: OIL | ET13: 330KV | EU13: AMP | EV13: MW | EW13: MX | EX13: 330KV | EY13: AMP | EZ13: MW | FA13: MX | FB13: 330KV | FC13: AMP | FD13: MW | FE13: MX | FF13: 330KV | FG13: AMP | FH13: MW | FI13: MX | FJ13: 330KV | FK13: AMP | FL13: MW | FM13: MX | FN13: 330KV | FO13: AMP | FP13: MW | FQ13: MX | FR13: 132KV | FS13: AMP | FT13: MW | FU13: MX | FV13: 132KV | FW13: AMP | FX13: MW | FY13: MX | GA13: 330KV | GB13: AMP | GC13: MW | GD13: MX | GE13: 330KV | GF13: AMP | GG13: MW | GH13: MX | GI13: 330KV | GJ13: AMP | GK13: MW | GL13: MX | GM13: 330KV | GN13: AMP | GO13: MW | GP13: MX | GQ13: 330KV | GR13: AMP | GS13: MW | GT13: MX | GU13: 330KV | GV13: AMP | GW13: MW | GX13: MX | GZ13: 132KV | HA13: 33KV | HB13: AMP | HC13: MW | HD13: MX | HE13: TAP | HF13: WIND | HG13: OIL | HH13: 132KV | HI13: 33KV | HJ13: AMP | HK13: MW | HL13: MX | HM13: TAP | HN13: WIND | HO13: OIL | HP13: 132KV | HQ13: 33KV | HR13: AMP | HS13: MW | HT13: MX | HU13: TAP | HV13: WIND | HW13: OIL | HY13: 132KV | HZ13: 33KV | IA13: AMP | IB13: MW | IC13: MX | ID13: TAP | IE13: WIND | IF13: OIL | IH13: 132KV | II13: 33KV | IJ13: AMP | IK13: MW | IL13: MX | IM13: TAP | IN13: WIND | IO13: OIL | IP13: 132KV | IQ13: 33KV | IR13: AMP | IS13: MW | IT13: MX | IU13: TAP | IV13: WIND | IW13: OIL | IY13: 132KV | IZ13: 33KV | JA13: AMP | JB13: MW | JC13: MX | JD13: TAP | JE13: WIND | JF13: OIL | JG13: 132KV | JH13: 33KV | JI13: AMP | JJ13: MW | JK13: MX | JL13: TAP | JM13: WIND | JN13: OIL | JP13: 132KV | JQ13: 33KV | JR13: AMP | JS13: MW | JT13: MX | JU13: TAP | JV13: WIND | JW13: OIL | JX13: 132KV | JY13: 33KV | JZ13: AMP | KA13: MW | KB13: MX | KC13: TAP | KD13: WIND | KE13: OIL | KG13: 132KV | KH13: 33KV | KI13: AMP | KJ13: MW | KK13: MX | KL13: TAP | KM13: WIND | KN13: OIL | KO13: 132KV | KP13: 33KV | KQ13: AMP | KR13: MW | KS13: MX | KT13: TAP | KU13: WIND | KV13: OIL | KX13: 132KV | KY13: 33KV | KZ13: AMP | LA13: MW | LB13: MX | LC13: TAP | LD13: WIND | LE13: OIL | LF13: 132KV | LG13: 33KV | LH13: AMP | LI13: MW | LJ13: MX | LK13: TAP | LL13: WIND | LM13: OIL | LO13: 330KV | LP13: AMP | LQ13: MW | LR13: MX | LS13: 330KV | LT13: MW | LU13: MX | LV13: KV | LW13: AMP | LX13: WIND | LY13: OIL | LZ13: TAP | MA13: MW | MB13: MX | MC13: KV | MD13: AMP | ME13: WIND | MF13: OIL | MG13: TAP | MH13: MW | MI13: MX | MJ13: KV | MK13: AMP | ML13: WIND | MM13: OIL | MN13: TAP | MT13: MW | MU13: MX | MV13: AMP | MW13: 33KV | MX13: WIND | MY13: OIL | MZ13: TAP | NB13: MW | NC13: MX | ND13: AMP | NE13: 33KV | NF13: WIND | NG13: OIL | NH13: TAP | NJ13: MW | NK13: MX | NL13: AMP | NM13: 33KV | NN13: WIND | NO13: OIL | NP13: TAP
A14: 0.041666667 | C14: 50.11 | D14: 340 | E14: 135 | F14: 51 | G14: 10.8 | I14: 6 | J14: 48 | K14: 47 | L14: 140 | M14: 67 | N14: 16.9 | P14: 6 | Q14: 54 | R14: 48 | S14: 343.4 | T14: 214.7 | U14: 129.9 | W14: 376.8 | X14: 142.7 | Y14: 88.3 | AA14: 342.8 | AB14: 289.6 | AC14: 184.8 | AE14: 342.5 | AF14: 320.1 | AG14: 166.1 | AI14: 348.6 | AJ14: 368.3 | AK14: 229.6 | AM14: 341.2 | AN14: 391.1 | AO14: 217.9 | AQ14: 135 | AR14: =F14 -> 51 | AS14: =G14 -> 10.8 | AU14: =L14 -> 140 | AV14: =M14 -> 67 | AW14: =N14 -> 16.9 | AY14: 135 | BE14: 33 | BF14: 245 | BG14: 2.7 | BI14: 22 | BJ14: 85 | BK14: 59 | BM14: 346 | BN14: 146 | BO14: 266 | BP14: 13.3 | BR14: 6 | BS14: 58 | BT14: 56 | BU14: =BM14 -> 346 | BV14: 284 | BW14: 167 | BX14: 36 | BY14: 339 | BZ14: 304 | CA14: 167 | CB14: 34 | CC14: 346 | CD14: 272 | CE14: 158 | CF14: 6 | CG14: 339 | CH14: 278 | CI14: 156 | CJ14: 6 | CK14: 353 | CL14: 133 | CM14: 89 | CN14: 7 | CO14: 336 | CP14: 273 | CQ14: 136 | CR14: 11 | CS14: 340 | CT14: 261 | CU14: 165 | CV14: 70 | CW14: 342 | CX14: 185 | CY14: 90 | CZ14: 54 | DA14: 328 | DB14: 195 | DC14: 90 | DD14: 54 | DE14: =BN14 -> 146 | DF14: 35 | DG14: =BO14 -> 266 | DH14: =BP14 -> 13.3 | DJ14: 7 | DK14: 60 | DL14: 53 | DM14: 5 | DN14: 343 | DO14: 142 | DP14: 36.13 | DQ14: 21.74 | DR14: 5.43 | DS14: 8 | DT14: 40 | DU14: 45.5 | EE14: 342 | EF14: 137 | EG14: 58 | EH14: 2.9 | EJ14: 9 | EK14: 46 | EL14: 48 | EN14: 106 | EO14: 4.7 | EQ14: 9 | ER14: 46 | ES14: 48 | ET14: 342 | EU14: 234 | EV14: 137.7 | EW14: -2.2 | EX14: 341 | EY14: 0 | EZ14: 0 | FA14: 0 | FB14: 341 | FC14: 4.02 | FD14: 2.04 | FE14: -0.9 | FF14: 340 | FG14: 0 | FH14: 0 | FI14: 0 | FJ14: 340 | FK14: 219 | FL14: 127.2 | FN14: 342 | FO14: 200 | FP14: 127.6 | FQ14: 7.2 | FR14: 137 | FS14: 100 | FT14: 20.11 | FV14: 137 | GA14: 343 | GB14: 298.36 | GC14: 188.04 | GD14: 24.46 | GE14: 342 | GF14: 316.09 | GG14: 185.27 | GH14: 28.73 | GI14: 342 | GJ14: 197.24 | GK14: -114.16 | GL14: 16.33 | GM14: 342 | GN14: 181.12 | GO14: -113.49 | GP14: -20.86 | GQ14: 343 | GR14: 112.25 | GS14: -73.12 | GT14: -7.87 | GU14: 342 | GV14: 123.09 | GW14: -72.12 | GX14: -8.71 | GZ14: 134KV | HA14: 34KV | HB14: 140 | HC14: 7 | HD14: 2.8 | HE14: 8 | HF14: 48 | HG14: 46 | HH14: 134KV | HI14: 34KV | HJ14: 41 | HK14: 2.05 | HL14: 0.82 | HM14: 5 | HN14: 58 | HO14: 58 | HP14: 134KV | HQ14: 34KV | HR14: 184 | HS14: 9.2 | HT14: 4.6 | HU14: 7 | HV14: 48 | HW14: 48 | HY14: 135 | HZ14: 33 | IA14: 104 | IB14: 5.2 | ID14: 2 | IE14: 58 | IF14: 48 | IH14: 141 | II14: 32.9 | IJ14: 109 | IK14: 5.3 | IL14: 6 | IM14: 4 | IN14: 47 | IO14: 46 | IP14: 141 | IQ14: 35.2 | IR14: 3 | IS14: 0.2 | IT14: 0.3 | IU14: 12 | IV14: 48 | IW14: 47 | IY14: 141.01 | IZ14: 35.29 | JC14: 4.86 | JD14: 3 | JE14: 62.71 | JF14: 44.22 | JG14: ON | JH14: ON | JI14: ON | JJ14: ON | JK14: ON | JL14: ON | JM14: ON | JN14: ON | JP14: 138 | JQ14: 32.5 | JR14: 0 | JS14: 0 | JT14: 0 | JU14: 2 | JV14: 34 | JW14: 34 | JX14: 138 | JY14: 33.9 | JZ14: 127 | KA14: 6.7 | KB14: 2.4 | KC14: 2 | KD14: 44 | KE14: 44 | KG14: O/S | KH14: O/S | KI14: O/S | KJ14: O/S | KL14: 1 | KM14: O/S | KN14: O/S | KO14: 136 | KP14: 33 | KQ14: 152 | KR14: 8.1 | KT14: 1 | KU14: 40 | KV14: 38 | KX14: 134 | KY14: 33 | KZ14: 169 | LA14: 8.3 | LB14: 2 | LC14: 3 | LD14: 49 | LE14: 49 | LF14: 134 | LG14: 33 | LH14: 259 | LI14: 12.7 | LJ14: 5 | LK14: 5 | LL14: 48 | LM14: 50 | LO14: 345 | LP14: 201 | LQ14: 117 | LR14: 74 | LS14: 334 | LT14: 51 | LU14: 5 | LV14: 142 | LW14: 90 | LX14: 52 | LY14: 50 | LZ14: 10 | MA14: 66 | MB14: 10 | MC14: 139 | MD14: 111 | ME14: 54 | MF14: 50 | MG14: 8 | MH14: TS | MI14: TS | MJ14: TS | MK14: TS | ML14: 40 | MM14: 40 | MN14: 5 | MT14: 12.2 | MU14: 4.5 | MV14: 210 | MW14: 36 | MX14: 44 | MY14: DEFECTIVE | MZ14: 5 | NB14: 14 | NC14: 5.8 | ND14: 254 | NE14: 36 | NF14: 44 | NG14: 45 | NH14: 6 | NJ14: TS | NK14: TS | NL14: TS | NM14: TS | NN14: 44 | NO14: 49 | NP14: 4
A15: 0.083333333 | C15: 50.13 | D15: 340 | E15: 135 | F15: 50 | G15: 10.8 | I15: 6 | J15: 48 | K15: 47 | L15: 140 | M15: 62 | N15: 15.9 | P15: 6 | Q15: 54 | R15: 48 | S15: 344.1 | T15: 223.6 | U15: 135.8 | W15: 377.4 | X15: 150.5 | Y15: 94.9 | AA15: 344.1 | AB15: 275.4 | AC15: 177.3 | AE15: 343.8 | AF15: 309.6 | AG15: 161.2 | AI15: 349.7 | AJ15: 357.3 | AK15: 225.1 | AM15: 342.5 | AN15: 380.2 | AO15: 212.6 | AQ15: 135 | AR15: =F15 -> 50 | AS15: =G15 -> 10.8 | AU15: =L15 -> 140 | AV15: =M15 -> 62 | AW15: =N15 -> 15.9 | AY15: 135 | BE15: 33 | BF15: 240 | BG15: 2.7 | BI15: 22 | BJ15: 85 | BK15: 59 | BM15: =BU15 -> 346 | BN15: 147 | BO15: 257 | BP15: 12.9 | BR15: 6 | BS15: 57 | BT15: 56 | BU15: 346 | BV15: 290 | BW15: 167 | BX15: 37 | BY15: 339 | BZ15: 305 | CA15: 168 | CB15: 35 | CC15: 346 | CD15: 282 | CE15: 102 | CF15: 4 | CG15: 339 | CH15: 288 | CI15: 161 | CJ15: 5 | CK15: 353 | CL15: 138 | CM15: 91 | CN15: 9 | CO15: 336 | CP15: 282 | CQ15: 140 | CR15: 11 | CS15: 339 | CT15: 276 | CU15: 74 | CV15: 79 | CW15: 343 | CX15: 183 | CY15: 89 | CZ15: 53 | DA15: 328 | DB15: 189 | DC15: 90 | DD15: 52 | DE15: =BN15 -> 147 | DF15: 35 | DG15: =BO15 -> 257 | DH15: =BP15 -> 12.9 | DJ15: 7 | DK15: 60 | DL15: 53 | DN15: 344 | DO15: 142 | DP15: 30.21 | DQ15: 17.38 | DR15: 3.67 | DS15: 8 | DT15: 36 | DU15: 46 | EE15: 343 | EF15: 137 | EG15: 68 | EH15: 2.9 | EJ15: 9 | EK15: 46 | EL15: 48 | EN15: 105 | EO15: 4.7 | EQ15: 9 | ER15: 46 | ES15: 48 | ET15: 343 | EU15: 235 | EV15: 137.5 | EW15: -1.1 | EX15: 341 | EY15: 0 | EZ15: 0 | FA15: 0 | FB15: 341 | FC15: 238 | FD15: 138 | FE15: -0.3 | FF15: 340 | FG15: 0 | FH15: 0 | FI15: 0 | FJ15: 340 | FK15: 219 | FL15: 127.2 | FN15: 342 | FO15: 200 | FP15: 127.8 | FQ15: 7.2 | FR15: 137 | FS15: 110 | FT15: 18.9 | FV15: 137 | GA15: 343 | GB15: 352.72 | GC15: 195.15 | GD15: 18.34 | GE15: 343 | GF15: 321.66 | GG15: 193.4 | GH15: 22.53 | GI15: 343 | GJ15: 194.17 | GK15: -113.16 | GL15: -13.57 | GM15: 343 | GN15: 212.63 | GO15: -112.99 | GP15: -20.02 | GQ15: 343 | GR15: 159.88 | GS15: 84.59 | GT15: 0 | GU15: 343 | GV15: 150.35 | GW15: -86.77 | GX15: -4.36 | GZ15: 134KV | HA15: 34KV | HB15: 100 | HC15: 5 | HD15: 2 | HE15: 8 | HF15: 48 | HG15: 46 | HH15: 134KV | HI15: 34KV | HJ15: 39 | HK15: 1.95 | HL15: 0.78 | HM15: 5 | HN15: 58 | HO15: 58 | HP15: 134KV | HQ15: 34KV | HR15: 185 | HS15: 9.25 | HT15: 4.625 | HU15: 7 | HV15: 48 | HW15: 48 | HY15: 135 | HZ15: 33 | IA15: 98 | IB15: 4.9 | ID15: 2 | IE15: 58 | IF15: 48 | IH15: 141 | II15: 32.9 | IJ15: 144 | IK15: 7.2 | IL15: 7.9 | IM15: 4 | IN15: 47 | IO15: 46 | IP15: 141 | IQ15: 35.3 | IR15: 3 | IS15: 0.2 | IT15: 0.3 | IU15: 12 | IV15: 48 | IW15: 47 | IY15: 141.54 | IZ15: 35.33 | JA15: 306.54 | JB15: 15.32 | JC15: 4.67 | JD15: 3 | JE15: 58.5 | JF15: 45.61 | JG15: ON | JH15: ON | JI15: ON | JJ15: ON | JK15: ON | JL15: ON | JM15: ON | JN15: ON | JP15: 136 | JQ15: 32.5 | JR15: 0 | JS15: 0 | JT15: 0 | JU15: 2 | JV15: 33 | JW15: 33 | JX15: 136 | JY15: 33.8 | JZ15: 128 | KA15: 6.2 | KB15: 2.1 | KC15: 2 | KD15: 44 | KE15: 43 | KG15: O/S | KH15: O/S | KI15: O/S | KJ15: O/S | KL15: 1 | KM15: O/S | KN15: O/S | KO15: 136 | KP15: 33 | KQ15: 142 | KR15: 7.7 | KT15: 1 | KU15: 40 | KV15: 38 | KX15: 131 | KY15: 33 | KZ15: 157 | LA15: 7.7 | LB15: 2 | LC15: 3 | LD15: 49 | LE15: 49 | LF15: 131 | LG15: 33 | LH15: 380 | LI15: 18.6 | LJ15: 5 | LK15: 5 | LL15: 48 | LM15: 50 | LO15: 346 | LP15: 194 | LQ15: 111 | LR15: 74 | LS15: 334 | LT15: 58 | LU15: 9.3 | LV15: 141 | LW15: 103 | LX15: 52 | LY15: 50 | LZ15: 10 | MA15: 53 | MB15: 14 | MC15: 140 | MD15: 91 | ME15: 52 | MF15: 49 | MG15: 8 | MH15: TS | MI15: TS | MJ15: TS | MK15: TS | ML15: 40 | MM15: 40 | MN15: 5 | MT15: 1.8 | MU15: 0.4 | MV15: 31 | MW15: 36 | MX15: 44 | MY15: DEFECTIVE | MZ15: 5 | NB15: 13.3 | NC15: 5.7 | ND15: 243 | NE15: 36 | NF15: 44 | NG15: 45 | NH15: 6 | NJ15: TS | NK15: TS | NL15: TS | NM15: TS | NN15: 44 | NO15: 49 | NP15: 4
A16: 0.125 | C16: 50.21 | D16: 340 | E16: 134 | F16: 78 | G16: 16.7 | I16: 6 | J16: 48 | K16: 47 | L16: 139 | M16: 77 | N16: 19.1 | P16: 6 | Q16: 54 | R16: 48 | S16: 342.1 | T16: 196.8 | U16: 119.5 | W16: 375.4 | X16: 125.3 | Y16: 73.4 | AA16: 342.1 | AB16: 305.9 | AC16: 192.9 | AE16: 342.2 | AF16: 339.5 | AG16: 173.5 | AI16: 347.5 | AJ16: 366.1 | AK16: 228.1 | AM16: 340.4 | AN16: 391.9 | AO16: 215.7 | AQ16: 134 | AR16: =F16 -> 78 | AS16: =G16 -> 16.7 | AU16: =L16 -> 139 | AV16: =M16 -> 77 | AW16: =N16 -> 19.1 | AY16: 134 | BE16: 33 | BF16: 226 | BG16: 2.5 | BI16: 22 | BJ16: 85 | BK16: 59 | BM16: 346 | BN16: 146 | BO16: 259 | BP16: 13 | BR16: 6 | BS16: 57 | BT16: 54 | BU16: =BM16 -> 346 | BV16: 286 | BW16: 168 | BX16: 31 | BY16: 339 | BZ16: 304 | CA16: 168 | CB16: 30 | CC16: 346 | CD16: 280 | CE16: 160 | CF16: 10 | CG16: 338 | CH16: 288 | CI16: 160 | CJ16: 7 | CK16: 352 | CL16: 133 | CM16: 89 | CN16: 6 | CO16: 336 | CP16: 276 | CQ16: 137 | CR16: 8 | CS16: 339 | CT16: 265 | CU16: 167 | CV16: 74 | CW16: 344 | CX16: 183 | CY16: 93 | CZ16: 52 | DA16: 328 | DB16: 189 | DC16: 92 | DD16: 46 | DE16: =BN16 -> 146 | DF16: 35 | DG16: =BO16 -> 259 | DH16: =BP16 -> 13 | DJ16: 7 | DK16: 61 | DL16: 54 | DN16: 344 | DO16: 142 | DP16: 29.73 | DQ16: 17.69 | DR16: 3.51 | DS16: 8 | DT16: 35 | DU16: 44.5 | EE16: 342 | EF16: 137 | EG16: 87 | EH16: 3.7 | EJ16: 9 | EK16: 46 | EL16: 48 | EN16: 105 | EO16: 4.7 | EQ16: 9 | ER16: 46 | ES16: 48 | ET16: 342 | EU16: 234 | EV16: 137.5 | EW16: -1.5 | EX16: 341 | EY16: 0 | EZ16: 0 | FA16: 0 | FB16: 341 | FC16: 237 | FD16: 138 | FE16: -0.9 | FF16: 340 | FG16: 0 | FH16: 0 | FI16: 0 | FJ16: 339 | FK16: 221 | FL16: 127.4 | FN16: 342 | FO16: 200 | FP16: 127.8 | FQ16: 7.8 | FR16: 137 | FS16: 109 | FT16: 17.71 | FV16: 137 | GA16: 342 | GB16: 335.87 | GC16: 195.66 | GD16: 19.43 | GE16: 342 | GF16: 344.66 | GG16: 195.15 | GH16: 22.53 | GI16: 342 | GJ16: 195.04 | GK16: -113.49 | GL16: -14.91 | GM16: 342 | GN16: 213.66 | GO16: -113.16 | GP16: -21.69 | GQ16: 342 | GR16: 161.49 | GS16: -85.35 | GT16: 0 | GU16: 342 | GV16: 144.63 | GW16: -82.42 | GX16: -4.36 | GZ16: 134KV | HA16: 34KV | HB16: 110 | HC16: 5.5 | HD16: 2.2 | HE16: 8 | HF16: 48 | HG16: 46 | HH16: 134KV | HI16: 34KV | HJ16: 96 | HK16: 4.8 | HL16: 1.92 | HM16: 5 | HN16: 58 | HO16: 58 | HP16: 134KV | HQ16: 34KV | HR16: 249 | HS16: 12.45 | HT16: 6.225 | HU16: 7 | HV16: 50 | HW16: 50 | HY16: 135 | HZ16: 33 | IA16: 92 | IB16: 4.6 | ID16: 2 | IE16: 58 | IF16: 48 | IH16: 140 | II16: 32.3 | IJ16: 184 | IK16: 9.3 | IL16: 10.1 | IM16: 4 | IN16: 47 | IO16: 46 | IP16: 140 | IQ16: 33.8 | IR16: 3 | IS16: 0.2 | IT16: 0.3 | IU16: 12 | IV16: 48 | IW16: 47 | IY16: 141.37 | IZ16: 35.51 | JA16: 300.02 | JB16: 15 | JC16: 4.67 | JD16: 3 | JE16: 54.48 | JF16: 45.61 | JG16: ON | JH16: ON | JI16: ON | JJ16: ON | JK16: ON | JL16: ON | JM16: ON | JN16: ON | JP16: 136 | JQ16: 32.5 | JR16: 0 | JS16: 0 | JT16: 0 | JU16: 2 | JV16: 33 | JW16: 33 | JX16: 136 | JY16: 34 | JZ16: 116 | KA16: 6.1 | KB16: 2.3 | KC16: 2 | KD16: 44 | KE16: 43 | KG16: O/S | KH16: O/S | KI16: O/S | KJ16: O/S | KL16: 1 | KM16: O/S | KN16: O/S | KO16: 135 | KP16: 32 | KQ16: 134 | KR16: 7.2 | KT16: 1 | KU16: 40 | KV16: 38 | KX16: 131 | KY16: 33 | KZ16: 157 | LA16: 7.7 | LB16: 2 | LC16: 3 | LD16: 49 | LE16: 49 | LF16: 131 | LG16: 33 | LH16: 376 | LI16: 18.4 | LJ16: 5 | LK16: 5 | LL16: 48 | LM16: 50 | LO16: 334 | LP16: 195 | LQ16: 109 | LR16: 73 | LS16: 343 | LT16: 55 | LU16: 1 | LV16: 144 | LW16: 67 | LX16: 45 | LY16: 41 | LZ16: 10 | MA16: 61 | MB16: 11.6 | MC16: 145 | MD16: 133 | ME16: 54 | MF16: 45 | MG16: 8 | MH16: TS | MI16: TS | MJ16: TS | MK16: TS | ML16: 40 | MM16: 40 | MN16: 5 | MT16: 2.2 | MU16: 0 | MV16: 42 | MW16: 36 | MX16: 34 | MY16: DEFECTIVE | MZ16: 5 | NB16: 9.1 | NC16: 3.2 | ND16: 158 | NE16: 36 | NF16: 44 | NG16: 45 | NH16: 6 | NJ16: TS | NK16: TS | NL16: TS | NM16: TS | NN16: 44 | NO16: 49 | NP16: 4
A17: 0.16666667 | C17: 50.27 | D17: 340 | E17: 136 | F17: 68 | G17: 14.9 | I17: 6 | J17: 48 | K17: 47 | L17: 140 | M17: 75 | N17: 18.7 | P17: 6 | Q17: 54 | R17: 48 | S17: 345.2 | T17: 174.1 | U17: 106.4 | W17: 378.6 | X17: 106.7 | Y17: 62.7 | AA17: 344.9 | AB17: 318.8 | AC17: 207.7 | AE17: 344.7 | AF17: 353.3 | AG17: 187.9 | AI17: 350.6 | AJ17: 365.3 | AK17: 230.8 | AM17: 343.2 | AN17: 387.9 | AO17: 218.7 | AQ17: 136 | AR17: =F17 -> 68 | AS17: =G17 -> 14.9 | AU17: =L17 -> 140 | AV17: =M17 -> 75 | AW17: =N17 -> 18.7 | AY17: 136 | BE17: 33 | BF17: 217 | BG17: 2.5 | BI17: 22 | BJ17: 85 | BK17: 59 | BM17: 346 | BN17: 147 | BO17: 272 | BP17: 13.6 | BR17: 6 | BS17: 57 | BT17: 56 | BU17: =BM17 -> 346 | BV17: 288 | BW17: 169 | BX17: 36 | BY17: 339 | BZ17: 305 | CA17: 168 | CB17: 34 | CC17: 345 | CD17: 260 | CE17: 156 | CF17: 4 | CG17: 338 | CH17: 256 | CI17: 154 | CJ17: 5 | CK17: 352 | CL17: 128 | CM17: 85 | CN17: 7 | CO17: 336 | CP17: 264 | CQ17: 130 | CR17: 9 | CS17: 339 | CT17: 256 | CU17: 161 | CV17: 72 | CW17: 346 | CX17: 198 | CY17: 98 | CZ17: 57 | DA17: 328 | DB17: 207 | DC17: 100 | DD17: 53 | DE17: =BN17 -> 147 | DF17: 35 | DG17: =BO17 -> 272 | DH17: =BP17 -> 13.6 | DJ17: 7 | DK17: 62 | DL17: 54 | DN17: 344 | DO17: 142 | DP17: 29.45 | DQ17: 16.96 | DR17: 3.44 | DS17: 8 | DT17: 34 | DU17: 44 | EE17: 342 | EF17: 137 | EG17: 87 | EH17: 3.7 | EJ17: 9 | EK17: 46 | EL17: 48 | EN17: 106 | EO17: 4.7 | EQ17: 9 | ER17: 46 | ES17: 48 | ET17: 342 | EU17: 234 | EV17: 137.5 | EW17: -0.5 | EX17: 342 | EY17: 0 | EZ17: 0 | FA17: 0 | FB17: 342 | FC17: 237 | FD17: 138 | FE17: -0.4 | FF17: 341 | FG17: 0 | FH17: 0 | FI17: 0 | FJ17: 341 | FK17: 220 | FL17: 128 | FN17: 343 | FO17: 202 | FP17: 128.3 | FQ17: 7.1 | FR17: 137 | FS17: 113 | FT17: 16.2 | FV17: 137 | GA17: 340 | GB17: 376.9 | GC17: 205.62 | GD17: 25.8 | GE17: 340 | GF17: 345.1 | GG17: 204.7 | GH17: 28.14 | GI17: 341 | GJ17: 194.17 | GK17: -113.66 | GL17: -12.23 | GM17: 342 | GN17: 192.55 | GO17: -112.82 | GP17: -20.44 | GQ17: 342 | GR17: 163.39 | GS17: -85.35 | GT17: -3.35 | GU17: 342 | GV17: 137.45 | GW17: -82.08 | GX17: -4.19 | GZ17: 134KV | HA17: 34KV | HB17: 109 | HC17: 5.45 | HD17: 2.18 | HE17: 8 | HF17: 48 | HG17: 46 | HH17: 134KV | HI17: 34KV | HJ17: 115 | HK17: 5.75 | HL17: 0 | HM17: 5 | HN17: 58 | HO17: 58 | HP17: 134KV | HQ17: 34KV | HR17: 240 | HS17: 12 | HT17: 6 | HU17: 7 | HV17: 50 | HW17: 50 | HY17: 135 | HZ17: 33 | IA17: 90 | IB17: 4.5 | ID17: 2 | IE17: 58 | IF17: 48 | IH17: 140 | II17: 32.7 | IJ17: 184 | IK17: 9.4 | IL17: 10.2 | IM17: 4 | IN17: 46 | IO17: 45 | IP17: 140 | IQ17: 35.2 | IR17: 3 | IS17: 0.2 | IT17: 0.3 | IU17: 12 | IV17: 47 | IW17: 46 | IY17: 141.42 | IZ17: 35.53 | JA17: 297.48 | JB17: 14.87 | JC17: 4.57 | JD17: 3 | JE17: 55.8 | JF17: 42.55 | JG17: ON | JH17: ON | JI17: ON | JJ17: ON | JK17: ON | JL17: ON | JM17: ON | JN17: ON | JP17: 137 | JQ17: 32.5 | JR17: 0 | JS17: 0 | JT17: 0 | JU17: 2 | JV17: 34 | JW17: 34 | JX17: 137 | JY17: 34.2 | JZ17: 113 | KA17: 5.9 | KB17: 2.3 | KC17: 2 | KD17: 43 | KE17: 43 | KG17: O/S | KH17: O/S | KI17: O/S | KJ17: O/S | KL17: 1 | KM17: O/S | KN17: O/S | KO17: 136 | KP17: 33 | KQ17: 105 | KR17: 5.7 | KT17: 1 | KU17: 40 | KV17: 38 | KX17: 129 | KY17: 32 | KZ17: 143 | LA17: 7 | LB17: 2 | LC17: 3 | LD17: 48 | LE17: 48 | LF17: 129 | LG17: 32 | LH17: 343 | LI17: 16.8 | LJ17: 5 | LK17: 5 | LL17: 49 | LM17: 49 | LO17: 335 | LP17: 200 | LQ17: 113 | LR17: 73 | LS17: 343 | LT17: 48 | LU17: 1.3 | LV17: 143 | LW17: 58 | LX17: 45 | LY17: 41 | LZ17: 10 | MA17: 58 | MB17: 12.3 | MC17: 143 | MD17: 124 | ME17: 53 | MF17: 45 | MG17: 8 | MH17: TS | MI17: TS | MJ17: TS | MK17: TS | ML17: 40 | MM17: 40 | MN17: 5 | MT17: 2.3 | MU17: 1 | MV17: 43 | MW17: 36 | MX17: 35 | MY17: DEFECTIVE | MZ17: 5 | NB17: 14 | NC17: 5.2 | ND17: 244 | NE17: 36 | NF17: 44 | NG17: 45 | NH17: 6 | NJ17: TS | NK17: TS | NL17: TS | NM17: TS | NN17: 44 | NO17: 49 | NP17: 4
A18: 0.20833333 | C18: 50.21 | D18: 339 | E18: 135 | F18: 70 | G18: 15.4 | I18: 6 | J18: 48 | K18: 47 | L18: 139 | M18: 79 | N18: 19.5 | P18: 6 | Q18: 54 | R18: 48 | S18: 343.1 | T18: 185.8 | U18: 113.2 | W18: 376.2 | X18: 112.6 | Y18: 65.7 | AA18: 342.9 | AB18: 349.4 | AC18: 227.2 | AE18: 342.9 | AF18: 392.8 | AG18: 206.6 | AI18: 348.3 | AJ18: 403.5 | AK18: 253.2 | AM18: 340.9 | AN18: 428.5 | AO18: 240.7 | AQ18: 135 | AR18: =F18 -> 70 | AS18: =G18 -> 15.4 | AU18: =L18 -> 139 | AV18: =M18 -> 79 | AW18: =N18 -> 19.5 | AY18: 135 | BE18: 33 | BF18: 234 | BG18: 2.6 | BI18: 22 | BJ18: 85 | BK18: 59 | BM18: 345 | BN18: 146 | BO18: 224 | BP18: 11.2 | BR18: 6 | BS18: 57 | BT18: 55 | BU18: =BM18 -> 345 | BV18: 355 | BW18: 205 | BX18: 36 | BY18: 338 | BZ18: 370 | CA18: 206 | CB18: 34 | CC18: 346 | CD18: 264 | CE18: 154 | CF18: 6 | CG18: 337 | CH18: 271 | CI18: 151 | CJ18: 7 | CK18: 352 | CL18: 136 | CM18: 90 | CN18: 8 | CO18: 335 | CP18: 278 | CQ18: 138 | CR18: 10 | CS18: 338 | CT18: 269 | CU18: 170 | CV18: 72 | CW18: 343 | CX18: 228 | CY18: 118 | CZ18: 60 | DA18: 327 | DB18: 238 | DC18: 120 | DD18: 48 | DE18: =BN18 -> 146 | DF18: 35 | DG18: =BO18 -> 224 | DH18: 11.2 | DJ18: 7 | DK18: 62 | DL18: 54 | DN18: 344 | DO18: 141 | DP18: 33.34 | DQ18: 18.91 | DR18: 4.78 | DS18: 8 | DT18: 37 | DU18: 39.7 | EE18: 342 | EF18: 137 | EG18: 84 | EH18: 3.5 | EJ18: 9 | EK18: 46 | EL18: 48 | EN18: 117 | EO18: 5.2 | EQ18: 9 | ER18: 46 | ES18: 48 | ET18: 342 | EU18: 235 | EV18: 137.6 | EW18: -0.9 | EX18: 341 | EY18: 0 | EZ18: 0 | FA18: 0 | FB18: 341 | FC18: 238 | FD18: 138 | FE18: -0.8 | FF18: 339 | FG18: 0 | FH18: 0 | FI18: 0 | FJ18: 340 | FK18: 220 | FL18: 126.7 | FN18: 342 | FO18: 200 | FP18: 127.3 | FQ18: 7.3 | FR18: 137 | FS18: 117 | FT18: 18.1 | FV18: 137 | GA18: 340 | GB18: 355.21 | GC18: 222.46 | GD18: 18.43 | GE18: 339 | GF18: 378.37 | GG18: 220.11 | GH18: 20.86 | GI18: 339 | GJ18: 207.94 | GK18: -117.51 | GL18: -21.44 | GM18: 339 | GN18: 189.92 | GO18: -117.01 | GP18: -27.97 | GQ18: 340 | GR18: 166.91 | GS18: -105.37 | GT18: 6.87 | GU18: 339 | GV18: 181.12 | GW18: -104.61 | GX18: 5.28 | GZ18: 134KV | HA18: 34KV | HB18: 81 | HC18: 4.05 | HD18: 1.62 | HE18: 8 | HF18: 48 | HG18: 48 | HH18: 134KV | HI18: 34KV | HJ18: 117 | HK18: 5.85 | HL18: 2.34 | HM18: 5 | HN18: 58 | HO18: 58 | HP18: 134KV | HQ18: 34KV | HR18: 148 | HS18: 7.4 | HT18: 3.7 | HU18: 7 | HV18: 54 | HW18: 54 | HY18: 135 | HZ18: 33 | IA18: 88 | IB18: 4.4 | ID18: 2 | IE18: 58 | IF18: 48 | IH18: 140 | II18: 32.7 | IJ18: 184 | IK18: 9.4 | IL18: 10.2 | IM18: 4 | IN18: 46 | IO18: 45 | IP18: 140 | IQ18: 35.2 | IR18: 3 | IS18: 0.2 | IT18: 0.3 | IU18: 12 | IV18: 47 | IW18: 46 | IY18: 141.28 | IZ18: 35.37 | JA18: 335.56 | JB18: 16.77 | JC18: 5.87 | JD18: 3 | JE18: 53.58 | JF18: 41.56 | JG18: ON | JH18: ON | JI18: ON | JJ18: ON | JK18: ON | JL18: ON | JM18: ON | JN18: ON | JP18: 137 | JQ18: 32.5 | JR18: 0 | JS18: 0 | JT18: 0 | JU18: 2 | JV18: 34 | JW18: 34 | JX18: 137 | JY18: 34.1 | JZ18: 115 | KA18: 6 | KB18: 2.2 | KC18: 2 | KD18: 43 | KE18: 43 | KG18: O/S | KH18: O/S | KI18: O/S | KJ18: O/S | KL18: 1 | KM18: O/S | KN18: O/S | KO18: 136 | KP18: 33 | KQ18: 142 | KR18: 7.8 | KT18: 1 | KU18: 40 | KV18: 38 | KX18: 132 | KY18: 33 | KZ18: 178 | LA18: 8.7 | LB18: 2 | LC18: 3 | LD18: 48 | LE18: 48 | LF18: 132 | LG18: 33 | LH18: 296 | LI18: 14.5 | LJ18: 5 | LK18: 5 | LL18: 49 | LM18: 49 | LO18: 335 | LP18: 183 | LQ18: 104 | LR18: 73 | LS18: 343 | LT18: 48 | LU18: 3.6 | LV18: 144 | LW18: 53 | LX18: 44 | LY18: 42 | LZ18: 10 | MA18: 59 | MB18: 0 | MC18: 143 | MD18: 136 | ME18: 54 | MF18: 45 | MG18: 8 | MH18: TS | MI18: TS | MJ18: TS | MK18: TS | ML18: 40 | MM18: 40 | MN18: 5 | MT18: 3 | MU18: 1 | MV18: 60 | MW18: 37 | MX18: 36 | MY18: DEFECTIVE | MZ18: 5 | NB18: 7.4 | NC18: 3.4 | ND18: 131 | NE18: 36 | NF18: 44 | NG18: 45 | NH18: 6 | NJ18: TS | NK18: TS | NL18: TS | NM18: TS | NN18: 44 | NO18: 49 | NP18: 4
A19: 0.25 | C19: 50 | D19: 341 | E19: 134 | F19: 64 | G19: 14.2 | I19: 6 | J19: 48 | K19: 47 | L19: 139 | M19: 86 | N19: 18.4 | P19: 6 | Q19: 54 | R19: 48 | S19: 341.5 | T19: 201.2 | U19: 121.8 | W19: 374.2 | X19: 125 | Y19: 75.2 | AA19: 340.6 | AB19: 384.3 | AC19: 212.1 | AE19: 340.9 | AF19: 379.4 | AG19: 193.7 | AI19: 346.5 | AJ19: 396.2 | AK19: 243.5 | AM19: 339.4 | AN19: 415.7 | AO19: 230.9 | AQ19: 134 | AR19: =F19 -> 64 | AS19: =G19 -> 14.2 | AU19: =L19 -> 139 | AV19: =M19 -> 86 | AW19: =N19 -> 18.4 | AY19: 134 | BE19: 33 | BF19: 272 | BG19: 3.1 | BI19: 22 | BJ19: 85 | BK19: 59 | BM19: 345 | BN19: 147 | BO19: =9+166+85 -> 260 | BP19: =260/20 -> 13 | BR19: 6 | BS19: 57 | BT19: 55 | BU19: =BM19 -> 345 | BV19: 347 | BW19: 205 | BX19: 33 | BY19: 337 | BZ19: 368 | CA19: 204 | CB19: 30 | CC19: 346 | CD19: 252 | CE19: 144 | CF19: 6 | CG19: 338 | CH19: 259 | CI19: 144 | CJ19: 7 | CK19: 351 | CL19: 140 | CM19: 93 | CN19: 7 | CO19: 355 | CP19: 285 | CQ19: 141 | CR19: 8 | CS19: 338 | CT19: 278 | CU19: 173 | CV19: 78 | CW19: 340 | CX19: 210 | CY19: 108 | CZ19: 57 | DA19: 327 | DB19: 216 | DC19: 109 | DD19: 47 | DE19: =BN19 -> 147 | DF19: 35 | DG19: =BO19 -> 260 | DH19: =BP19 -> 13 | DJ19: 7 | DK19: 62 | DL19: 54 | DN19: 343 | DO19: 141 | DP19: 41.28 | DQ19: 23.3 | DR19: 6.12 | DS19: 8 | DT19: 38 | DU19: 39.8 | EE19: 342 | EF19: 137 | EG19: 86 | EH19: 3.6 | EJ19: 9 | EK19: 46 | EL19: 48 | EN19: 103 | EO19: 4.6 | EQ19: 9 | ER19: 46 | ES19: 48 | ET19: 342 | EU19: 235 | EV19: 137.6 | EW19: -1.2 | EX19: 341 | EY19: 0 | EZ19: 0 | FA19: 0 | FB19: 341 | FC19: 237 | FD19: 138 | FE19: -1 | FF19: 340 | FG19: 0 | FH19: 0 | FI19: 0 | FJ19: 340 | FK19: 220 | FL19: 127 | FN19: 342 | FO19: 201 | FP19: 127.3 | FQ19: 7 | FR19: 137 | FS19: 96 | FT19: 21.91 | FV19: 137 | GA19: 341 | GB19: 389.06 | GC19: 241.47 | GD19: 23.37 | GE19: 341 | GF19: 368.43 | GG19: 215.67 | GH19: 27.3 | GI19: 341 | GJ19: 220.69 | GK19: -127.39 | GL19: -26.13 | GM19: 341 | GN19: 202.37 | GO19: -126.47 | GP19: -33 | GQ19: 341 | GR19: 176.87 | GS19: -111.73 | GT19: 0 | GU19: 341 | GV19: 192.41 | GW19: -110.88 | GX19: 0 | GZ19: 134KV | HA19: 34KV | HB19: 98 | HC19: 4.9 | HD19: 1.96 | HE19: 8 | HF19: 48 | HG19: 48 | HH19: 134KV | HI19: 34KV | HJ19: 124 | HK19: 6.2 | HL19: 2.48 | HM19: 5 | HN19: 58 | HO19: 58 | HP19: 134KV | HQ19: 34KV | HR19: 161 | HS19: 8.05 | HT19: 4.025 | HU19: 7 | HV19: 55 | HW19: 55 | HY19: 135 | HZ19: 33 | IA19: 94 | IB19: 4.7 | ID19: 2 | IE19: 58 | IF19: 48 | IH19: 140 | II19: 32.5 | IJ19: 172 | IK19: 8.6 | IL19: 9.4 | IM19: 4 | IN19: 46 | IO19: 45 | IP19: 140 | IQ19: 34.8 | IR19: 3 | IS19: 0.2 | IT19: 0.3 | IU19: 12 | IV19: 47 | IW19: 46 | IY19: 140.67 | IZ19: 35.12 | JA19: 341.84 | JB19: 17.09 | JC19: 7.26 | JD19: 3 | JE19: 57.53 | JF19: 41.56 | JG19: ON | JH19: ON | JI19: ON | JJ19: ON | JK19: ON | JL19: ON | JM19: ON | JN19: ON | JP19: 136 | JQ19: 32.5 | JR19: 0 | JS19: 0 | JT19: 0 | JU19: 2 | JV19: 35 | JW19: 35 | JX19: 136 | JY19: 33.8 | JZ19: 126 | KA19: 6.8 | KB19: 2.3 | KC19: 2 | KD19: 43 | KE19: 42 | KG19: O/S | KH19: O/S | KI19: O/S | KJ19: O/S | KL19: 1 | KM19: O/S | KN19: O/S | KO19: 136 | KP19: 33 | KQ19: 154 | KR19: 8.6 | KT19: 1 | KU19: 40 | KV19: 38 | KX19: 132 | KY19: 33 | KZ19: 194 | LA19: 9.5 | LB19: 2 | LC19: 3 | LD19: 48 | LE19: 48 | LF19: 132 | LG19: 33 | LH19: 320 | LI19: 15.7 | LJ19: 5 | LK19: 5 | LL19: 49 | LM19: 49 | LO19: 338 | LP19: 199 | LQ19: 113 | LR19: 73 | LS19: 343 | LT19: 49 | LU19: 0.5 | LV19: 143 | LW19: 64 | LX19: 45 | LY19: 43 | LZ19: 10 | MA19: 59 | MB19: 0.5 | MC19: 143 | MD19: 125 | ME19: 53 | MF19: 46 | MG19: 8 | MH19: TS | MI19: TS | MJ19: TS | MK19: TS | ML19: 40 | MM19: 40 | MN19: 5 | MT19: 1.7 | MU19: 0.1 | MV19: 42 | MW19: 37 | MX19: 36 | MY19: DEFECTIVE | MZ19: 5 | NB19: 13 | NC19: 4.7 | ND19: 241 | NE19: 35 | NF19: 44 | NG19: 45 | NH19: 6 | NJ19: TS | NK19: TS | NL19: TS | NM19: TS | NN19: 44 | NO19: 49 | NP19: 4
A20: 0.29166667 | C20: 50.34 | D20: 341 | E20: 136 | F20: 105 | G20: 23.5 | I20: 6 | J20: 48 | K20: 47 | L20: 141 | M20: 88 | N20: 22.2 | P20: 6 | Q20: 54 | R20: 48 | S20: 346.7 | T20: 193.1 | U20: 119.6 | W20: 380.5 | X20: 113.7 | Y20: 71.5 | AA20: 346.4 | AB20: 295.7 | AC20: 198.4 | AE20: 346.6 | AF20: 331.1 | AG20: 181.8 | AI20: 352.3 | AJ20: 372 | AK20: 236.2 | AM20: 344.6 | AN20: 394 | AO20: 226.1 | AQ20: 136 | AR20: =F20 -> 105 | AS20: =G20 -> 23.5 | AU20: =L20 -> 141 | AV20: =M20 -> 88 | AW20: =N20 -> 22.2 | AY20: 136 | BE20: 33 | BF20: 115 | BG20: 3.6 | BI20: 22 | BJ20: 81 | BK20: 54 | BM20: 346 | BN20: 147 | BO20: 293 | BP20: 14.7 | BR20: 6 | BS20: 57 | BT20: 56 | BU20: =BM20 -> 346 | BV20: 357 | BW20: 205 | BX20: 46 | BY20: 338 | BZ20: 372 | CA20: 206 | CB20: 42 | CC20: 346 | CD20: 260 | CE20: 148 | CF20: 4 | CG20: 338 | CH20: 267 | CI20: 148 | CJ20: 4 | CK20: 352 | CL20: 142 | CM20: 97 | CN20: 6 | CO20: 336 | CP20: 305 | CQ20: 151 | CR20: 8 | CS20: 339 | CT20: 300 | CU20: 186 | CV20: 87 | CW20: 342 | CX20: 193 | CY20: 93 | CZ20: 56 | DA20: 327 | DB20: 198 | DC20: 95 | DD20: 55 | DE20: =BN20 -> 147 | DF20: 35 | DG20: 293 | DH20: 14.7 | DJ20: 7 | DK20: 60 | DL20: 52 | DN20: 344 | DO20: 141 | DP20: 45.84 | DQ20: 26.33 | DR20: 7.97 | DS20: 8 | DT20: 34 | DU20: 38 | EE20: 342 | EF20: 137 | EG20: 71 | EH20: 3 | EJ20: 9 | EK20: 46 | EL20: 48 | EN20: 100 | EO20: 4.3 | EQ20: 9 | ER20: 46 | ES20: 48 | ET20: 342 | EU20: 234 | EV20: 137.9 | EW20: -4.4 | EX20: 343 | EY20: 0 | EZ20: 0 | FA20: 0 | FB20: 343 | FC20: 236 | FD20: 138 | FE20: -4 | FF20: 342 | FG20: 0 | FH20: 0 | FI20: 0 | FJ20: 342 | FK20: 220 | FL20: 127 | FN20: 342 | FO20: 202 | FP20: 127.8 | FQ20: 1.9 | FR20: 137 | FS20: 96 | FT20: 11.21 | FV20: 137 | GA20: 346 | GB20: 365.47 | GC20: 230.33 | GD20: 13.23 | GE20: 346 | GF20: 388.33 | GG20: 229.08 | GH20: 17.59 | GI20: 346 | GJ20: 225.43 | GK20: -131.92 | GL20: -16.67 | GM20: 346 | GN20: 208.53 | GO20: -131.5 | GP20: -24.21 | GQ20: 346 | GR20: 159.63 | GS20: -103.27 | GT20: 2.85 | GU20: 346 | GV20: 172.8 | GW20: -100.93 | GX20: 0 | GZ20: 134KV | HA20: 34KV | HB20: 114 | HC20: 5.7 | HD20: 2.28 | HE20: 8 | HF20: 50 | HG20: 48 | HH20: 134KV | HI20: 34KV | HJ20: 139 | HK20: 6.95 | HL20: 2.78 | HM20: 5 | HN20: 58 | HO20: 58 | HP20: 134KV | HQ20: 34KV | HR20: 317 | HS20: 15.85 | HT20: 7.925 | HU20: 7 | HV20: 55 | HW20: 55 | HY20: 136 | HZ20: 33 | IA20: 52 | IB20: 2.6 | ID20: 2 | IE20: 58 | IF20: 48 | IH20: 140 | II20: 32.5 | IJ20: 187 | IK20: 9.4 | IL20: 10.3 | IM20: 4 | IN20: 45 | IO20: 44 | IP20: 140 | IQ20: 35.1 | IR20: 3 | IS20: 0.2 | IT20: 0.3 | IU20: 12 | IV20: 46 | IW20: 45 | IY20: 140.96 | IZ20: 35.1 | JA20: 453.28 | JB20: 22.66 | JC20: 8.22 | JD20: 3 | JE20: 58.5 | JF20: 42.55 | JG20: ON | JH20: ON | JI20: ON | JJ20: ON | JK20: ON | JL20: ON | JM20: ON | JN20: ON | JP20: 140 | JQ20: 32.5 | JR20: 0 | JS20: 0 | JT20: 0 | JU20: 2 | JV20: 35 | JW20: 35 | JX20: 140 | JY20: 34.8 | JZ20: 145 | KA20: 7.8 | KB20: 2.9 | KC20: 2 | KD20: 43 | KE20: 42 | KG20: O/S | KH20: O/S | KI20: O/S | KJ20: O/S | KL20: 1 | KM20: O/S | KN20: O/S | KO20: 140 | KP20: 34 | KQ20: 15 | KR20: 0.7 | KT20: 1 | KU20: 40 | KV20: 38 | KX20: 131 | KY20: 33 | KZ20: 204 | LA20: 10 | LB20: 2 | LC20: 3 | LD20: 46 | LE20: 46 | LF20: 131 | LG20: 33 | LH20: 333 | LI20: 16.3 | LJ20: 5 | LK20: 5 | LL20: 44 | LM20: 45 | LO20: 343 | LP20: 316 | LQ20: 116 | LR20: 72 | LS20: 343 | LT20: 54 | LU20: 6.5 | LV20: 141 | LW20: 96 | LX20: 48 | LY20: 45 | LZ20: 10 | MA20: 62 | MB20: 13 | MC20: 139 | MD20: 120 | ME20: 52 | MF20: 45 | MG20: 8 | MH20: TS | MI20: TS | MJ20: TS | MK20: TS | ML20: 40 | MM20: 40 | MN20: 5 | MT20: 8 | MU20: 4.1 | MV20: 140 | MW20: 36 | MX20: 44 | MY20: DEFECTIVE | MZ20: 5 | NB20: 8 | NC20: 3.5 | ND20: 145 | NE20: 36 | NF20: 44 | NG20: 45 | NH20: 6 | NJ20: TS | NK20: TS | NL20: TS | NM20: TS | NN20: 44 | NO20: 49 | NP20: 4
A21: 0.33333333 | C21: 50.3 | D21: 340 | E21: 135 | F21: 53 | G21: 11.6 | I21: 6 | J21: 46 | K21: 46 | L21: 140 | M21: 71 | N21: 17.3 | P21: 6 | Q21: 55 | R21: 49 | S21: 344.4 | T21: 198.1 | U21: 120.5 | W21: 378.8 | X21: 112.5 | Y21: 74.8 | AA21: 345.2 | AB21: 307.2 | AC21: 201.4 | AE21: 344.7 | AF21: 344.1 | AG21: 185.2 | AI21: 350.1 | AJ21: 369.1 | AK21: 236 | AM21: 342.8 | AN21: 393.4 | AO21: 223.4 | AQ21: 135 | AR21: =F21 -> 53 | AS21: =G21 -> 11.6 | AU21: =L21 -> 140 | AV21: =M21 -> 71 | AW21: =N21 -> 17.3 | AY21: 135 | BE21: 33 | BF21: 121 | BG21: 4 | BI21: 22 | BJ21: 81 | BK21: 54 | BM21: 346 | BN21: 146 | BO21: 286 | BP21: 14.3 | BR21: 6 | BS21: 57 | BT21: 56 | BU21: =BM21 -> 346 | BV21: 347 | BW21: 205 | BX21: 33 | BY21: 338 | BZ21: 370 | CA21: 205 | CB21: 31 | CC21: 346 | CD21: 270 | CE21: 156 | CF21: 16 | CG21: 338 | CH21: 274 | CI21: 153 | CJ21: 8 | CK21: 352 | CL21: 147 | CM21: 98 | CN21: 1 | CO21: 335 | CP21: 303 | CQ21: 150 | CR21: 8 | CS21: 338 | CT21: 299 | CU21: 184 | CV21: 93 | CW21: 339 | CX21: 205 | CY21: 102 | CZ21: 58 | DA21: 327 | DB21: 211 | DC21: 104 | DD21: 53 | DE21: =BN21 -> 146 | DF21: 35 | DG21: =BO21 -> 286 | DH21: =BP21 -> 14.3 | DJ21: 7 | DK21: 60 | DL21: 52 | DN21: 343 | DO21: 141 | DP21: 34.78 | DQ21: 21.99 | DR21: 3.78 | DS21: 8 | DT21: 34 | DU21: 40.3 | EE21: 342 | EF21: 137 | EG21: 72 | EH21: 3.1 | EJ21: 9 | EK21: 46 | EL21: 48 | EN21: 100 | EO21: 4.3 | EQ21: 9 | ER21: 46 | ES21: 48 | ET21: 342 | EU21: 341 | EV21: 139.9 | EW21: -4.5 | EX21: 339 | EY21: 0 | EZ21: 0 | FA21: 0 | FB21: 339 | FC21: 241 | FD21: 139.3 | FE21: -10.2 | FF21: 339 | FG21: 0 | FH21: 0 | FI21: 0 | FJ21: 340 | FK21: 221 | FL21: 129 | FN21: 342 | FO21: 202 | FP21: 127.7 | FQ21: -1.5 | FR21: 137 | FS21: 96 | FT21: 15.41 | FV21: 137 | GA21: 341 | GB21: 375.44 | GC21: 284.93 | GD21: 17.09 | GE21: 341 | GF21: 386.57 | GG21: 222.12 | GH21: 26.3 | GI21: 341 | GJ21: 225.96 | GK21: -130.41 | GL21: -3.94 | GM21: 341 | GN21: 207.79 | GO21: -130.66 | GP21: -11.31 | GQ21: 341 | GR21: 154.75 | GS21: -95.48 | GT21: -15.75 | GU21: 341 | GV21: 168.67 | GW21: -94.98 | GX21: -16.5 | GZ21: 134KV | HA21: 34KV | HB21: 90 | HC21: 4.5 | HD21: 1.8 | HE21: 8 | HF21: 50 | HG21: 48 | HH21: 134KV | HI21: 34KV | HJ21: 44 | HK21: 2.2 | HL21: 0.88 | HM21: 5 | HN21: 58 | HO21: 58 | HP21: 134KV | HQ21: 34KV | HR21: 190 | HS21: 9.5 | HT21: 4.75 | HU21: 7 | HV21: 56 | HW21: 56 | HY21: 135 | HZ21: 33 | IA21: 50 | IB21: 2.5 | ID21: 2 | IE21: 58 | IF21: 48 | IH21: 141 | II21: 33.2 | IJ21: 10 | IK21: 0.5 | IL21: 0.5 | IM21: 4 | IN21: 45 | IO21: 44 | IP21: 141 | IQ21: 34.8 | IR21: 118 | IS21: 6.3 | IT21: 7 | IU21: 12 | IV21: 46 | IW21: 45 | IY21: 140.78 | IZ21: 35.27 | JA21: 422.8 | JB21: 21.14 | JC21: 6.72 | JD21: 3 | JE21: 60.62 | JF21: 44.22 | JG21: ON | JH21: ON | JI21: ON | JJ21: ON | JK21: ON | JL21: ON | JM21: ON | JN21: ON | JP21: 137 | JQ21: 32.5 | JR21: 0 | JS21: 0 | JT21: 0 | JU21: 2 | JV21: 38 | JW21: 36 | JX21: 137 | JY21: 34.1 | JZ21: 104 | KA21: 5.7 | KB21: 2.2 | KC21: 2 | KD21: 43 | KE21: 43 | KG21: O/S | KH21: O/S | KI21: O/S | KJ21: O/S | KL21: 1 | KM21: O/S | KN21: O/S | KO21: 136 | KP21: 33 | KQ21: 129 | KR21: 7 | KT21: 1 | KU21: 42 | KV21: 40 | KX21: 130 | KY21: 33 | KZ21: 241 | LA21: 11.8 | LB21: 2.1 | LC21: 3 | LD21: 46 | LE21: 46 | LF21: 130 | LG21: 33 | LH21: 343 | LI21: 16.8 | LJ21: 5 | LK21: 5 | LL21: 44 | LM21: 45 | LO21: 345 | LP21: 211 | LQ21: 123 | LR21: 73 | LS21: 333 | LT21: 53 | LU21: 8.5 | LV21: 141 | LW21: 94 | LX21: 47 | LY21: 45 | LZ21: 10 | MA21: 70 | MB21: 12.7 | MC21: 139 | MD21: 117 | ME21: 50 | MF21: 44 | MG21: 8 | MH21: TS | MI21: TS | MJ21: TS | MK21: TS | ML21: 40 | MM21: 40 | MN21: 5 | MT21: 7.5 | MU21: 2.5 | MV21: 126 | MW21: 36 | MX21: 34 | MY21: DEFECTIVE | MZ21: 5 | NB21: 8.9 | NC21: 4 | ND21: 162 | NE21: 36 | NF21: 44 | NG21: 45 | NH21: 6 | NJ21: TS | NK21: TS | NL21: TS | NM21: TS | NN21: 44 | NO21: 49 | NP21: 4
A22: 0.375 | C22: 50.42 | D22: 338 | E22: 133 | F22: 31 | G22: 6.8 | I22: 6 | J22: 46 | K22: 46 | L22: 138 | M22: 75 | N22: 18.1 | P22: 6 | Q22: 55 | R22: 49 | S22: 338.4 | T22: 243.8 | U22: 146.9 | W22: 371.2 | X22: 155.4 | Y22: 94.2 | AA22: SG | AE22: 339 | AF22: 610.4 | AG22: 331.9 | AI22: 344.1 | AJ22: 374.3 | AK22: 229.1 | AM22: 336.6 | AN22: 398.4 | AO22: 217.4 | AQ22: 133 | AR22: =F22 -> 31 | AS22: =G22 -> 6.8 | AU22: =L22 -> 138 | AV22: =M22 -> 75 | AW22: =N22 -> 18.1 | AY22: 133 | BE22: 33 | BF22: 129 | BG22: 4.2 | BI22: 22 | BJ22: 81 | BK22: 54 | BM22: 344 | BN22: 145 | BO22: 263 | BP22: 13.2 | BR22: 6 | BS22: 59 | BT22: 58 | BU22: =BM22 -> 344 | BV22: 343 | BW22: 204 | BX22: 24 | BY22: 336 | BZ22: 369 | CA22: 204 | CB22: 23 | CC22: 344 | CD22: 278 | CE22: 160 | CF22: 12 | CG22: 337 | CH22: 288 | CI22: 158 | CJ22: 12 | CK22: 350 | CL22: 153 | CM22: 102 | CN22: 2 | CO22: 334 | CP22: 318 | CQ22: 157 | CR22: 4 | CS22: 337 | CT22: 315 | CU22: 191 | CV22: 95 | CW22: 338 | CX22: 176 | CY22: 89 | CZ22: 48 | DA22: 325 | DB22: 182 | DC22: 90 | DD22: 41 | DE22: =BN22 -> 145 | DF22: 35 | DG22: =BO22 -> 263 | DH22: =BP22 -> 13.2 | DJ22: 7 | DK22: 60 | DL22: 54 | DN22: 343 | DO22: 141 | DP22: 38.68 | DQ22: 21.86 | DR22: 6.12 | DS22: 8 | DT22: 39 | DU22: 43 | EE22: 341 | EF22: 137 | EG22: 72 | EH22: 3.1 | EJ22: 9 | EK22: 46 | EL22: 48 | EN22: 97 | EO22: 5.1 | EQ22: 9 | ER22: 46 | ES22: 48 | ET22: 341 | EU22: 341 | EV22: 140 | EW22: -12 | EX22: 338 | EY22: 0 | EZ22: 0 | FA22: 0 | FB22: 339 | FC22: 240 | FD22: 139.3 | FE22: -11 | FF22: 339 | FG22: 0 | FH22: 0 | FI22: 0 | FJ22: 340 | FK22: 224 | FL22: 129.9 | FN22: 342 | FO22: 204 | FP22: 130.9 | FQ22: -3 | FR22: 137 | FS22: 81 | FT22: 12 | FV22: 137 | GA22: 338 | GB22: 378.66 | GC22: 232.01 | GD22: 25.63 | GE22: 338 | GF22: 404.6 | GG22: 229.17 | GH22: 29.57 | GI22: 338 | GJ22: 234.29 | GK22: -134.18 | GL22: -2.85 | GM22: 338 | GN22: 214.39 | GO22: -133.93 | GP22: -10.3 | GQ22: 338 | GR22: 159 | GS22: -97.33 | GT22: -18.18 | GU22: 338 | GV22: 174.97 | GW22: -18.68 | GX22: -18.69 | GZ22: 134KV | HA22: 34KV | HB22: 91 | HC22: 4.55 | HD22: 1.82 | HE22: 8 | HF22: 50 | HG22: 48 | HH22: 134KV | HI22: 34KV | HJ22: 46 | HK22: 2.3 | HL22: 0.92 | HM22: 5 | HN22: 58 | HO22: 58 | HP22: 134KV | HQ22: 34KV | HR22: 96 | HS22: 4.8 | HT22: 2.4 | HU22: 7 | HV22: 56 | HW22: 56 | HY22: 135 | HZ22: 33 | IA22: 52 | IB22: 2.6 | ID22: 2 | IE22: 58 | IF22: 48 | IH22: 140 | II22: 33.2 | IJ22: 10 | IK22: 0.5 | IL22: 0.5 | IM22: 4 | IN22: 42 | IO22: 41 | IP22: 140 | IQ22: 34.4 | IR22: 123 | IS22: 6.5 | IT22: 7.2 | IU22: 12 | IV22: 50 | IW22: 48 | IY22: 140.72 | IZ22: 35.69 | JA22: 334.86 | JB22: 16.74 | JC22: 7.19 | JD22: 3 | JE22: 62.64 | JF22: 47.37 | JG22: ON | JH22: ON | JI22: ON | JJ22: ON | JK22: ON | JL22: ON | JM22: ON | JN22: ON | JP22: 137 | JQ22: 32.5 | JR22: 0 | JS22: 0 | JT22: 0 | JU22: 2 | JV22: 40 | JW22: 39 | JX22: 137 | JY22: 34.1 | JZ22: 107 | KA22: 5.9 | KB22: 2.3 | KC22: 2 | KD22: 45 | KE22: 45 | KG22: O/S | KH22: O/S | KI22: O/S | KJ22: O/S | KL22: 1 | KM22: O/S | KN22: O/S | KO22: 137 | KP22: 33 | KQ22: 62 | KR22: 3.7 | KT22: 1 | KU22: 42 | KV22: 40 | KX22: 132 | KY22: 33 | KZ22: 255 | LA22: 12.5 | LB22: 2.1 | LC22: 3 | LD22: 47 | LE22: 47 | LF22: 132 | LG22: 33 | LH22: 296 | LI22: 14.5 | LJ22: 5 | LK22: 5 | LL22: 44 | LM22: 46 | LO22: 344 | LP22: 193 | LQ22: 113 | LR22: 73 | LS22: 334 | LT22: 58 | LU22: 9.4 | LV22: 141 | LW22: 101 | LX22: 48 | LY22: 44 | LZ22: 10 | MA22: 55 | MB22: 17 | MC22: 140 | MD22: 92 | ME22: 48 | MF22: 44 | MG22: 8 | MH22: TS | MI22: TS | MJ22: TS | MK22: TS | ML22: 40 | MM22: 40 | MN22: 5 | MT22: 2 | MU22: 0 | MV22: 37 | MW22: 36 | MX22: 34 | MY22: DEFECTIVE | MZ22: 5 | NB22: 16 | NC22: 6.4 | ND22: 284 | NE22: 36 | NF22: 44 | NG22: 45 | NH22: 6 | NJ22: TS | NK22: TS | NL22: TS | NM22: TS | NN22: 44 | NO22: 49 | NP22: 4
A23: 0.41666667 | C23: 50.26 | D23: 340 | E23: 135 | F23: 32 | G23: 6.9 | I23: 6 | J23: 46 | K23: 46 | L23: 140 | M23: 58 | N23: 14.2 | P23: 6 | Q23: 55 | R23: 49 | S23: 344.2 | T23: 206.5 | U23: 125.6 | W23: 377.6 | X23: 141.6 | Y23: 91.3 | AA23: SG | AE23: 344.9 | AF23: 565.7 | AG23: 319.3 | AI23: 349.9 | AJ23: 340.5 | AK23: 212.6 | AM23: 342.3 | AN23: 364.6 | AO23: 202.7 | AQ23: 135 | AR23: =F23 -> 32 | AS23: =G23 -> 6.9 | AU23: =L23 -> 140 | AV23: =M23 -> 58 | AW23: =N23 -> 14.2 | AY23: 135 | BE23: 36 | BF23: 22 | BG23: 0.7 | BI23: 22 | BJ23: 81 | BK23: 54 | BM23: 345 | BN23: 147 | BO23: 194 | BP23: 9.7 | BR23: 6 | BS23: 60 | BT23: 60 | BU23: =BM23 -> 345 | BV23: 332 | BW23: 203 | BX23: 33 | BY23: 337 | BZ23: 369 | CA23: 205 | CB23: 30 | CC23: 345 | CD23: 280 | CE23: 160 | CF23: 8 | CG23: 337 | CH23: 291 | CI23: 153 | CJ23: 11 | CK23: 351 | CL23: 157 | CM23: 162 | CN23: 10 | CO23: 334 | CP23: 326 | CQ23: 161 | CR23: 7 | CS23: 338 | CT23: 317 | CU23: 191 | CV23: 104 | CW23: 340 | CX23: 198 | CY23: 91 | CZ23: 59 | DA23: 325 | DB23: 204 | DC23: 92 | DD23: 60 | DE23: =BN23 -> 147 | DF23: 35.1 | DG23: 194 | DH23: 9.7 | DJ23: 7 | DK23: 60 | DL23: 55 | DN23: 343 | DO23: 141 | DP23: 37.94 | DQ23: 21.27 | DR23: 6.22 | DS23: 8 | DT23: 36 | DU23: 42.7 | EE23: 343 | EF23: 138 | EG23: 71 | EH23: 3 | EJ23: 9 | EK23: 46 | EL23: 49 | EN23: 100 | EO23: 4.5 | EQ23: 9 | ER23: 47 | ES23: 49 | ET23: 342 | EU23: 210 | EV23: 123.3 | EW23: 0.4 | EX23: 340 | EY23: 1 | EZ23: 0 | FA23: 0 | FB23: 341 | FC23: 212 | FD23: 124 | FE23: 2.3 | FF23: 340 | FG23: 1 | FH23: 0 | FI23: 0 | FJ23: 343 | FK23: 198 | FL23: 115.1 | FN23: 343 | FO23: 195 | FP23: 115.4 | FQ23: 8.7 | FR23: 137 | FS23: 93 | FT23: 9.01 | FV23: 138 | GA23: 343 | GB23: 3338.8 | GC23: 209.31 | GD23: 20.44 | GE23: 343 | GF23: 360.93 | GG23: 208.64 | GH23: 23.62 | GI23: 343 | GJ23: 200.2 | GK23: -116 | GL23: -17.51 | GM23: 343 | GN23: 184.64 | GO23: -115.33 | GP23: -23.54 | GQ23: 343 | GR23: 152.28 | GS23: -94.4 | GT23: 0 | GU23: 343 | GV23: 166.62 | GW23: -94.06 | GX23: -2.76 | GZ23: 134KV | HA23: 34KV | HB23: 105 | HC23: 5.25 | HD23: 2.1 | HE23: 8 | HF23: 50 | HG23: 48 | HH23: 134KV | HI23: 34KV | HJ23: 45 | HK23: 2.25 | HL23: 0.9 | HM23: 5 | HN23: 58 | HO23: 58 | HP23: 134KV | HQ23: 34KV | HR23: 106 | HS23: 5.3 | HT23: 2.65 | HU23: 7 | HV23: 56 | HW23: 56 | HY23: 135 | HZ23: 33 | IA23: 66 | IB23: 3.3 | ID23: 2 | IE23: 58 | IF23: 48 | IH23: 140 | II23: 33.2 | IJ23: 10 | IK23: 0.5 | IL23: 0.5 | IM23: 4 | IN23: 42 | IO23: 41 | IP23: 140 | IQ23: 34.4 | IR23: 123 | IS23: 6.5 | IT23: 7.2 | IU23: 12 | IV23: 50 | IW23: 48 | IY23: 140.83 | IZ23: 35.13 | JA23: 331.2 | JB23: 16.56 | JC23: 7.31 | JD23: 3 | JE23: 61.77 | JF23: 47.37 | JG23: ON | JH23: ON | JI23: ON | JJ23: ON | JK23: ON | JL23: ON | JM23: ON | JN23: ON | JP23: 137 | JQ23: 32.3 | JR23: 0 | JS23: 0 | JT23: 0 | JU23: 2 | JV23: 42 | JW23: 42 | JX23: 137 | JY23: 34.5 | JZ23: 108 | KA23: 5.7 | KB23: 2.3 | KC23: 2 | KD23: 47 | KE23: 47 | KG23: O/S | KH23: O/S | KI23: O/S | KJ23: O/S | KL23: 1 | KM23: O/S | KN23: O/S | KO23: 136 | KP23: 33 | KQ23: 115 | KR23: 6.2 | KT23: 1 | KU23: 42 | KV23: 40 | KX23: 134 | KY23: 32 | KZ23: 171 | LA23: 8.4 | LB23: 4.1 | LC23: 3 | LD23: 47 | LE23: 47 | LF23: 134 | LG23: 33 | LH23: 296 | LI23: 14.5 | LJ23: 5 | LK23: 5 | LL23: 44 | LM23: 46 | LO23: 345 | LP23: 189 | LQ23: 111 | LR23: 74 | LS23: 334 | LT23: 51 | LU23: 7 | LV23: 141 | LW23: 88 | LX23: 47 | LY23: 45 | LZ23: 10 | MA23: 60 | MB23: 14 | MC23: 139 | MD23: 101 | ME23: 49 | MF23: 45 | MG23: 8 | MH23: TS | MI23: TS | MJ23: TS | MK23: TS | ML23: 40 | MM23: 40 | MN23: 5 | MT23: 5 | MU23: 1 | MV23: 87 | MW23: 36 | MX23: 34 | MY23: DEFECTIVE | MZ23: 5 | NB23: 15 | NC23: 6 | ND23: 262 | NE23: 36 | NF23: 44 | NG23: 45 | NH23: 6 | NJ23: TS | NK23: TS | NL23: TS | NM23: TS | NN23: 44 | NO23: 49 | NP23: 4
A24: 0.45833333 | C24: 50.15 | D24: 339 | E24: 135 | F24: 60 | G24: 13.3 | I24: 6 | J24: 52 | K24: 51 | L24: 139 | M24: 60 | N24: 14.8 | P24: 6 | Q24: 54 | R24: 49 | S24: 343.4 | T24: 204.3 | U24: 124.1 | W24: 376.3 | X24: 126.6 | Y24: 82.5 | AA24: SG | AE24: 343.2 | AF24: 570.1 | AG24: 320.9 | AI24: 349.2 | AJ24: 333.7 | AK24: 204.9 | AM24: 341.5 | AN24: 356.3 | AO24: 195.9 | AQ24: 135 | AR24: =F24 -> 60 | AS24: =G24 -> 13.3 | AU24: =L24 -> 139 | AV24: =M24 -> 60 | AW24: =N24 -> 14.8 | AY24: 135 | BE24: 36 | BF24: 21 | BG24: 0.7 | BI24: 22 | BJ24: 81 | BK24: 54 | BM24: 344 | BN24: 146 | BO24: 225 | BP24: 11.3 | BR24: 6 | BS24: 64 | BT24: 65 | BU24: =BM24 -> 344 | BV24: 281 | BW24: 166 | BX24: 22 | BY24: 337 | BZ24: 302 | CA24: 168 | CB24: 40 | CC24: 345 | CD24: 282 | CE24: 162 | CF24: 14 | CG24: 337 | CH24: 283 | CI24: 161 | CJ24: 13 | CK24: 351 | CL24: 146 | CM24: 98 | CN24: 2 | CO24: 334 | CP24: 302 | CQ24: 150 | CR24: 7 | CS24: 338 | CT24: 312 | CU24: 182 | CV24: 113 | CW24: 339 | CX24: 165 | CY24: 70 | CZ24: 51 | DA24: 326 | DB24: 172 | DC24: 72 | DD24: 58 | DE24: =BN24 -> 146 | DF24: 35.2 | DG24: =BO24 -> 225 | DH24: =BP24 -> 11.3 | DJ24: 7 | DK24: 60 | DL24: 54 | DN24: 343 | DO24: 141 | DP24: 37.65 | DQ24: 21.27 | DR24: 6.32 | DS24: 8 | DT24: 39 | DU24: 44 | EE24: 342 | EF24: 137 | EG24: 71 | EH24: 3.1 | EJ24: 9 | EK24: 48 | EL24: 51 | EN24: 101 | EO24: 4.5 | EQ24: 9 | ER24: 49 | ES24: 51 | ET24: 341 | EU24: 237 | EV24: 139.2 | EW24: -0.9 | EX24: 339 | EY24: 1 | EZ24: 0 | FA24: 0 | FB24: 340 | FC24: 237 | FD24: 138.3 | FE24: 0.7 | FF24: 339 | FG24: 1 | FH24: 0 | FI24: 0 | FJ24: 342 | FK24: 225 | FL24: 130.6 | FN24: 343 | FO24: 221 | FP24: 130.7 | FQ24: 10.8 | FR24: 137 | FS24: 90 | FT24: 9.31 | FV24: 137 | GA24: 342 | GB24: 330.15 | GC24: 202.41 | GD24: 25.71 | GE24: 342 | GF24: 348.4 | GG24: 201.77 | GH24: 30.07 | GI24: 342 | GJ24: 228.75 | GK24: -131.08 | GL24: -16.58 | GM24: 342 | GN24: 210.14 | GO24: -130.91 | GP24: -23.12 | GQ24: 342 | GR24: 116.79 | GS24: -72.37 | GT24: -7.87 | GU24: 342 | GV24: 128.61 | GW24: -71.61 | GX24: -9.63 | GZ24: 134KV | HA24: 34KV | HB24: 125 | HC24: 6.25 | HD24: 2.5 | HE24: 8 | HF24: 50 | HG24: 48 | HH24: 134KV | HI24: 34KV | HJ24: 135 | HK24: 6.75 | HL24: 2.7 | HM24: 5 | HN24: 58 | HO24: 58 | HP24: 134KV | HQ24: 34KV | HR24: 107 | HS24: 5.35 | HT24: 2.675 | HU24: 7 | HV24: 56 | HW24: 56 | HY24: 135 | HZ24: 33 | IA24: 68 | IB24: 3.4 | ID24: 2 | IE24: 58 | IF24: 48 | IH24: 141 | II24: 33.6 | IJ24: 12 | IK24: 0.6 | IL24: 0.6 | IM24: 4 | IN24: 42 | IO24: 41 | IP24: 140 | IQ24: 34.8 | IR24: 121 | IS24: 6.4 | IT24: 7.2 | IU24: 12 | IV24: 50 | IW24: 48 | IY24: 140.68 | IZ24: 35.12 | JA24: 325.26 | JB24: 16.26 | JC24: 7.42 | JD24: 3 | JE24: 61.77 | JF24: 49.14 | JG24: ON | JH24: ON | JI24: ON | JJ24: ON | JK24: ON | JL24: ON | JM24: ON | JN24: ON | JP24: 137 | JQ24: 32.5 | JR24: 0 | JS24: 0 | JT24: 0 | JU24: 2 | JV24: 46 | JW24: 45 | JX24: 137 | JY24: 34.5 | JZ24: 109 | KA24: 5.7 | KB24: 2.4 | KC24: 2 | KD24: 50 | KE24: 50 | KG24: O/S | KH24: O/S | KI24: O/S | KJ24: O/S | KL24: 1 | KM24: O/S | KN24: O/S | KO24: 136 | KP24: 33 | KQ24: 100 | KR24: 5.4 | KT24: 1 | KU24: 42 | KV24: 40 | KX24: 134 | KY24: 32 | KZ24: 228 | LA24: 11.2 | LB24: 4.1 | LC24: 3 | LD24: 47 | LE24: 47 | LF24: 134 | LG24: 33 | LH24: 228 | LI24: 11.2 | LJ24: 5 | LK24: 5 | LL24: 44 | LM24: 46 | LO24: 346 | LP24: 184 | LQ24: 109 | LR24: 74 | LS24: 333 | LT24: 49 | LU24: 5 | LV24: 141 | LW24: 84 | LX24: 48 | LY24: 45 | LZ24: 10 | MA24: 60 | MB24: 13 | MC24: 139 | MD24: 100 | ME24: 49 | MF24: 46 | MG24: 8 | MH24: TS | MI24: TS | MJ24: TS | MK24: TS | ML24: 40 | MM24: 40 | MN24: 5 | MT24: 4 | MU24: 7 | MV24: 83 | MW24: 36 | MX24: 34 | MY24: DEFECTIVE | MZ24: 5 | NB24: 13 | NC24: 5.4 | ND24: 240 | NE24: 36 | NF24: 44 | NG24: 45 | NH24: 6 | NJ24: TS | NK24: TS | NL24: TS | NM24: TS | NN24: 44 | NO24: 49 | NP24: 4
A25: 0.5 | C25: 50.29 | D25: 341 | E25: 136 | F25: 35 | G25: 7.5 | I25: 6 | J25: 52 | K25: 51 | L25: 141 | M25: 60 | N25: 14.8 | P25: 6 | Q25: 54 | R25: 52 | S25: 346.7 | T25: 181.1 | U25: 108.8 | W25: 380.3 | X25: 139.4 | Y25: 74.6 | AA25: SG | AE25: 346.1 | AF25: 588.7 | AG25: 330.4 | AI25: 352.6 | AJ25: 321.6 | AK25: 202.2 | AM25: 345.2 | AN25: 339.5 | AO25: 192.8 | AQ25: 136 | AR25: =F25 -> 35 | AS25: =G25 -> 7.5 | AU25: =L25 -> 141 | AV25: =M25 -> 60 | AW25: =N25 -> 14.8 | AY25: 136 | BE25: 36 | BF25: 24 | BG25: 0.8 | BI25: 22 | BJ25: 85 | BK25: 66 | BM25: 345 | BN25: 146 | BO25: 233 | BP25: 11.7 | BR25: 6 | BS25: 66 | BT25: 68 | BU25: =BM25 -> 345 | BV25: 283 | BW25: 167 | BX25: 27 | BY25: 337 | BZ25: 305 | CA25: 169 | CB25: 25 | CC25: 345 | CD25: 288 | CE25: 164 | CF25: 10 | CG25: 337 | CH25: 295 | CI25: 164 | CJ25: 10 | CK25: 351 | CL25: 154 | CM25: 103 | CN25: 4 | CO25: 334 | CP25: 313 | CQ25: 155 | CR25: 8 | CS25: 338 | CT25: 312 | CU25: 184 | CV25: 110 | CW25: 341 | CX25: 170 | CY25: 63 | CZ25: 54 | DA25: 327 | DB25: 179 | DC25: 68 | DD25: 69 | DE25: =BN25 -> 146 | DF25: 35.4 | DG25: =BO25 -> 233 | DH25: =BP25 -> 11.7 | DJ25: 7 | DK25: 58 | DL25: 57 | DN25: 344 | DO25: 141 | DP25: 32.05 | DQ25: 18.25 | DR25: 4.95 | DS25: 8 | DT25: 40 | DU25: 49 | EE25: 346 | EF25: 139 | EG25: 91 | EH25: 3.9 | EJ25: 9 | EK25: 50 | EL25: 51 | EN25: 101 | EO25: 4.5 | EQ25: 9 | ER25: 50 | ES25: 51 | ET25: 344 | EU25: 236 | EV25: 139 | EW25: -10.3 | EX25: 342 | EY25: 1 | EZ25: 0 | FA25: 0 | FB25: 343 | FC25: 236 | FD25: 138.2 | FE25: -9.9 | FF25: 342 | FG25: 1 | FH25: 0 | FI25: 0 | FJ25: 346 | FK25: 220 | FL25: 128.6 | FN25: 346 | FO25: 217 | FP25: 129.4 | FQ25: 9.6 | FR25: 139 | FS25: 100 | FT25: 11.71 | FV25: 139 | GA25: 345 | GB25: 325.76 | GC25: 204.12 | GD25: 7.71 | GE25: 345 | GF25: 345.39 | GG25: 202.19 | GH25: 9.97 | GI25: 345 | GJ25: 222.59 | GK25: -130.33 | GL25: -5.7 | GM25: 345 | GN25: 205.45 | GO25: -130.24 | GP25: -13.9 | GQ25: 345 | GR25: 117.82 | GS25: -73.79 | GT25: 0 | GU25: 345 | GV25: 130.57 | GW25: -72.87 | GX25: 0 | GZ25: 134KV | HA25: 34KV | HB25: 121 | HC25: 6.05 | HD25: 2.42 | HE25: 8 | HF25: 50 | HG25: 48 | HH25: 134KV | HI25: 34KV | HJ25: 49 | HK25: 2.45 | HL25: 0.98 | HM25: 5 | HN25: 58 | HO25: 58 | HP25: 134KV | HQ25: 34KV | HR25: 110 | HS25: 5.5 | HT25: 2.75 | HU25: 7 | HV25: 56 | HW25: 56 | HY25: 136 | HZ25: 33 | IA25: 124 | IB25: 6.2 | ID25: 2 | IE25: 58 | IF25: 48 | IH25: 143 | II25: 33.8 | IJ25: 12 | IK25: 0.6 | IL25: 0.6 | IM25: 4 | IN25: 44 | IO25: 42 | IP25: 143 | IQ25: 35.2 | IR25: 121 | IS25: 6.4 | IT25: 7.2 | IU25: 12 | IV25: 52 | IW25: 50 | IY25: 141.04 | IZ25: 35.31 | JA25: 342.42 | JB25: 17.12 | JC25: 6.1 | JD25: 3 | JE25: 61.77 | JF25: 45.61 | JG25: ON | JH25: ON | JI25: ON | JJ25: ON | JK25: ON | JL25: ON | JM25: ON | JN25: ON | JP25: 138 | JQ25: 32.6 | JR25: 0 | JS25: 0 | JT25: 0 | JU25: 2 | JV25: 48 | JW25: 46 | JX25: 138 | JY25: 34 | JZ25: 102 | KA25: 5.5 | KB25: 2.4 | KC25: 2 | KD25: 54 | KE25: 53 | KG25: O/S | KH25: O/S | KI25: O/S | KJ25: O/S | KL25: 1 | KM25: O/S | KN25: O/S | KO25: 137 | KP25: 33 | KQ25: 100 | KR25: 5.5 | KT25: 1 | KU25: 46 | KV25: 44 | KX25: 138 | KY25: 34 | KZ25: 228 | LA25: 11.2 | LB25: 4.1 | LC25: 3 | LD25: 51 | LE25: 51 | LF25: 138 | LG25: 34 | LH25: 243 | LI25: 11.9 | LJ25: 5 | LK25: 5 | LL25: 49 | LM25: 50 | LO25: 346 | LP25: 178 | LQ25: 105 | LR25: 74 | LS25: 335 | LT25: 43 | LU25: 2 | LV25: 142 | LW25: 75 | LX25: 49 | LY25: 47 | LZ25: 10 | MA25: 59 | MB25: 11 | MC25: 140 | MD25: 103 | ME25: 51 | MF25: 48 | MG25: 8 | MH25: TS | MI25: TS | MJ25: TS | MK25: TS | ML25: 40 | MM25: 40 | MN25: 5 | MT25: 4 | MU25: 1 | MV25: 73 | MW25: 36 | MX25: 34 | MY25: DEFECTIVE | MZ25: 5 | NB25: 14.2 | NC25: 6.2 | ND25: 255 | NE25: 36 | NF25: 44 | NG25: 45 | NH25: 6 | NJ25: TS | NK25: TS | NL25: TS | NM25: TS | NN25: 44 | NO25: 49 | NP25: 4
A26: 0.54166667 | C26: 49.97 | D26: 341 | E26: 136 | F26: 61 | G26: 13.5 | I26: 6 | J26: 52 | K26: 51 | L26: 140 | M26: 60 | N26: 14.8 | P26: 6 | Q26: 54 | R26: 52 | S26: 345.5 | T26: 180.8 | U26: 106.6 | W26: 378.7 | X26: 132.3 | Y26: 69.3 | AA26: SG | AE26: 345.2 | AF26: 623.7 | AG26: 345.7 | AI26: 351.6 | AJ26: 329.3 | AK26: 206.6 | AM26: 343.8 | AN26: 350.4 | AO26: 196.4 | AQ26: 136 | AR26: =F26 -> 61 | AS26: =G26 -> 13.5 | AU26: =L26 -> 140 | AV26: =M26 -> 60 | AW26: =N26 -> 14.8 | AY26: 136 | BE26: 36 | BF26: 23 | BG26: 0.8 | BI26: 22 | BJ26: 85 | BK26: 66 | BM26: 344 | BN26: 146 | BO26: 166 | BP26: 8.3 | BR26: 6 | BS26: 72 | BT26: 74 | BU26: =BM26 -> 344 | BV26: 282 | BW26: 167 | BX26: 22 | BY26: 337 | BZ26: 304 | CA26: 168 | CB26: 20 | CC26: 345 | CD26: 278 | CE26: 160 | CF26: 12 | CG26: 337 | CH26: 291 | CI26: 159 | CJ26: 12 | CK26: 351 | CL26: 147 | CM26: 99 | CN26: 5 | CO26: 334 | CP26: 310 | CQ26: 152 | CR26: 10 | CS26: 338 | CT26: 318 | CU26: 180 | CV26: 116 | CW26: 341 | CX26: 168 | CY26: 66 | CZ26: 54 | DA26: 327 | DB26: 177 | DC26: 71 | DD26: 64 | DE26: =BN26 -> 146 | DF26: 35.4 | DG26: =BO26 -> 166 | DH26: =BP26 -> 8.3 | DJ26: 7 | DK26: 57 | DL26: 55 | DN26: 343 | DO26: 141 | DP26: 32.41 | DQ26: 17.7 | DR26: 5.31 | DS26: 8 | DT26: 46 | DU26: 46 | EE26: 344 | EF26: 138 | EG26: 71 | EH26: 3 | EJ26: 9 | EK26: 52 | EL26: 53 | EN26: 105 | EO26: 4.6 | EQ26: 9 | ER26: 52 | ES26: 53 | ET26: 343 | EU26: 237 | EV26: 139 | EW26: -11.2 | EX26: 342 | EY26: 1 | EZ26: 0 | FA26: 0 | FB26: 342 | FC26: 237 | FD26: 138.4 | FE26: -10 | FF26: 342 | FG26: 1 | FH26: 0 | FI26: 0 | FJ26: 344 | FK26: 229 | FL26: 133 | FN26: 344 | FO26: 225 | FP26: 133.5 | FQ26: 1.3 | FR26: 138 | FS26: 79 | FT26: 10 | FV26: 138 | GA26: 345 | GB26: 313.47 | GC26: 196.49 | GD26: 4.44 | GE26: 345 | GF26: 333.09 | GG26: 196.16 | GH26: 7.62 | GI26: 345 | GJ26: 222.89 | GK26: -130.83 | GL26: -7.12 | GM26: 345 | GN26: 205.01 | GO26: -131.16 | GP26: -14.91 | GQ26: 345 | GR26: 109.9 | GS26: -68.35 | GT26: 3.27 | GU26: 345 | GV26: 123.68 | GW26: -68.01 | GX26: 0 | GZ26: 134KV | HA26: 34KV | HB26: 127 | HC26: 6.35 | HD26: 2.54 | HE26: 8 | HF26: 50 | HG26: 48 | HH26: 134KV | HI26: 34KV | HJ26: 157 | HK26: 7.85 | HL26: 3.14 | HM26: 5 | HN26: 58 | HO26: 58 | HP26: 134KV | HQ26: 34KV | HR26: 108 | HS26: 5.4 | HT26: 2.7 | HU26: 7 | HV26: 56 | HW26: 56 | HY26: 136 | HZ26: 33 | IA26: 16 | IB26: 0.8 | ID26: 2 | IE26: 58 | IF26: 48 | IH26: 142 | II26: 33.7 | IJ26: 24 | IK26: 1.2 | IL26: 1.3 | IM26: 4 | IN26: 44 | IO26: 42 | IP26: 142 | IQ26: 34.8 | IR26: 108 | IS26: 5.6 | IT26: 6.3 | IU26: 12 | IV26: 52 | IW26: 50 | IY26: 140.97 | IZ26: 35.34 | JA26: 335.77 | JB26: 16.78 | JC26: 5.98 | JD26: 3 | JE26: 62.64 | JF26: 48.24 | JG26: ON | JH26: ON | JI26: ON | JJ26: ON | JK26: ON | JL26: ON | JM26: ON | JN26: ON | JP26: 139 | JQ26: 32.7 | JR26: 0 | JS26: 0 | JT26: 0 | JU26: 2 | JV26: 49 | JW26: 47 | JX26: 139 | JY26: 34.9 | JZ26: 105 | KA26: 5.5 | KB26: 2.5 | KC26: 2 | KD26: 55 | KE26: 54 | KG26: O/S | KH26: O/S | KI26: O/S | KJ26: O/S | KL26: 1 | KM26: O/S | KN26: O/S | KO26: 138 | KP26: 34 | KQ26: 62 | KR26: 3.6 | KT26: 1 | KU26: 46 | KV26: 44 | KX26: 134 | KY26: 34 | KZ26: 39 | LA26: 1.9 | LB26: 0.2 | LC26: 3 | LD26: 51 | LE26: 51 | LF26: 134 | LG26: 34 | LH26: 251 | LI26: 12.3 | LJ26: 5 | LK26: 5 | LL26: 49 | LM26: 50 | LO26: 346 | LP26: 190 | LQ26: 114 | LR26: 74 | LS26: 335 | LT26: 47 | LU26: 5 | LV26: 142 | LW26: 82 | LX26: 51 | LY26: 49 | LZ26: 10 | MA26: 67 | MB26: 15 | MC26: 140 | MD26: 108 | ME26: 53 | MF26: 50 | MG26: 8 | MH26: TS | MI26: TS | MJ26: TS | MK26: TS | ML26: 40 | MM26: 40 | MN26: 5 | MT26: 4 | MU26: 2 | MV26: 75 | MW26: 36 | MX26: 34 | MY26: DEFECTIVE | MZ26: 5 | NB26: 15 | NC26: 6.2 | ND26: 261 | NE26: 36 | NF26: 44 | NG26: 45 | NH26: 6 | NJ26: TS | NK26: TS | NL26: TS | NM26: TS | NN26: 44 | NO26: 49 | NP26: 4
